<?xml version="1.0" encoding="UTF-8"?>
<robot name="xarm7_for_linker">
  <joint name="AssemblerFixedJoint" type="fixed">
    <origin xyz="0. -0. 0." rpy="0. 0. 1.5707964"/>
    <parent link="UF_ROBOT_link7"/>
    <child link="linker_hand_base"/>
  </joint>
  <joint name="index_joint0" type="revolute">
    <origin xyz="-0.025865 -0.026698 0.15421 " rpy="0. 0. 0."/>
    <parent link="hand_base_link"/>
    <child link="linker_hand_l20_left_isaac_sim_index_link0"/>
    <axis xyz="1. 0. 0."/>
    <limit lower="0." upper="0.26" effort="100." velocity="0.9999999"/>
  </joint>
  <joint name="index_joint1" type="revolute">
    <origin xyz="0.011115 -0.0047959 0. " rpy="0. 0. 0."/>
    <parent link="linker_hand_l20_left_isaac_sim_index_link0"/>
    <child link="linker_hand_l20_left_isaac_sim_index_link1"/>
    <axis xyz="0. 1. 0."/>
    <limit lower="0." upper="1.3999999" effort="100." velocity="0.9999999"/>
  </joint>
  <joint name="index_joint2" type="revolute">
    <origin xyz="-0.0034454 0.0010465 0.044883 " rpy="0. 0. 0."/>
    <parent link="linker_hand_l20_left_isaac_sim_index_link1"/>
    <child link="linker_hand_l20_left_isaac_sim_index_link2"/>
    <axis xyz="0. 1. 0."/>
    <limit lower="0." upper="1.08" effort="100." velocity="0.9999999"/>
  </joint>
  <joint name="index_joint3" type="revolute">
    <origin xyz="0.0084126 -0.0012 0.03069 " rpy="0. 0. 0."/>
    <parent link="linker_hand_l20_left_isaac_sim_index_link2"/>
    <child link="linker_hand_l20_left_isaac_sim_index_link3"/>
    <axis xyz="0. 1. 0."/>
    <limit lower="0." upper="1.3789309" effort="0." velocity="17453.2925199"/>
  </joint>
  <joint name="index_joint4" type="fixed">
    <origin xyz="-0.013709 0.0063957 0.024981 " rpy="0. 1.5707964 0. "/>
    <parent link="linker_hand_l20_left_isaac_sim_index_link3"/>
    <child link="linker_hand_l20_left_isaac_sim_index_link4"/>
  </joint>
  <joint name="joint1" type="revolute">
    <origin xyz="0. 0. 0.267" rpy="0. 0. 0."/>
    <parent link="world"/>
    <child link="UF_ROBOT_link1"/>
    <axis xyz="0. 0. 1."/>
    <limit lower="-6.2831853" upper="6.2831853" effort="50." velocity="3.1399998"/>
  </joint>
  <joint name="joint2" type="revolute">
    <origin xyz="0. 0. 0." rpy="-1.5708 0. 0. "/>
    <parent link="UF_ROBOT_link1"/>
    <child link="UF_ROBOT_link2"/>
    <axis xyz="0. 0. 1."/>
    <limit lower="-2.059" upper="2.0943998" effort="50." velocity="3.1399998"/>
  </joint>
  <joint name="joint3" type="revolute">
    <origin xyz="0. -0.293 -0. " rpy="1.5708 0. 0. "/>
    <parent link="UF_ROBOT_link2"/>
    <child link="UF_ROBOT_link3"/>
    <axis xyz="0. 0. 1."/>
    <limit lower="-6.2831853" upper="6.2831853" effort="30." velocity="3.1399998"/>
  </joint>
  <joint name="joint4" type="revolute">
    <origin xyz="0.0525 0. 0. " rpy="1.5708 0. 0. "/>
    <parent link="UF_ROBOT_link3"/>
    <child link="UF_ROBOT_link4"/>
    <axis xyz="0. 0. 1."/>
    <limit lower="-0.19198" upper="3.9269999" effort="30." velocity="3.1399998"/>
  </joint>
  <joint name="joint5" type="revolute">
    <origin xyz="0.0775 -0.3425 0. " rpy="1.5708 0. 0. "/>
    <parent link="UF_ROBOT_link4"/>
    <child link="UF_ROBOT_link5"/>
    <axis xyz="0. 0. 1."/>
    <limit lower="-6.2831853" upper="6.2831853" effort="30." velocity="3.1399998"/>
  </joint>
  <joint name="joint6" type="revolute">
    <origin xyz="0. -0. 0." rpy="1.5708001 0. 0. "/>
    <parent link="UF_ROBOT_link5"/>
    <child link="UF_ROBOT_link6"/>
    <axis xyz="0. 0. 1."/>
    <limit lower="-1.6929699" upper="3.1415927" effort="20." velocity="3.1399998"/>
  </joint>
  <joint name="joint7" type="revolute">
    <origin xyz="0.076 0.097 0. " rpy="-1.5708 0. 0. "/>
    <parent link="UF_ROBOT_link6"/>
    <child link="UF_ROBOT_link7"/>
    <axis xyz="0. 0. 1."/>
    <limit lower="-6.2831853" upper="6.2831853" effort="20." velocity="3.1399998"/>
  </joint>
  <joint name="linker_hand_base_joint" type="fixed">
    <origin xyz="0. 0. 0." rpy="0. 0. 0."/>
    <parent link="linker_hand_base"/>
    <child link="hand_base_link"/>
  </joint>
  <joint name="little_joint0" type="revolute">
    <origin xyz="-0.02467 0.038102 0.14521 " rpy="0. 0. 0."/>
    <parent link="hand_base_link"/>
    <child link="linker_hand_l20_left_isaac_sim_little_link0"/>
    <axis xyz="1. 0. 0."/>
    <limit lower="0." upper="0.26" effort="100." velocity="0.9999999"/>
  </joint>
  <joint name="little_joint1" type="revolute">
    <origin xyz="0.011115 -0.0047959 0. " rpy="0. 0. 0."/>
    <parent link="linker_hand_l20_left_isaac_sim_little_link0"/>
    <child link="linker_hand_l20_left_isaac_sim_little_link1"/>
    <axis xyz="0. 1. 0."/>
    <limit lower="0." upper="1.3999999" effort="100." velocity="0.9999999"/>
  </joint>
  <joint name="little_joint2" type="revolute">
    <origin xyz="-0.0034454 0.0010465 0.044883 " rpy="0. 0. 0."/>
    <parent link="linker_hand_l20_left_isaac_sim_little_link1"/>
    <child link="linker_hand_l20_left_isaac_sim_little_link2"/>
    <axis xyz="0. 1. 0."/>
    <limit lower="0." upper="1.08" effort="100." velocity="0.9999999"/>
  </joint>
  <joint name="little_joint3" type="revolute">
    <origin xyz="0.0084126 -0.0012 0.03069 " rpy="0. 0. 0."/>
    <parent link="linker_hand_l20_left_isaac_sim_little_link2"/>
    <child link="linker_hand_l20_left_isaac_sim_little_link3"/>
    <axis xyz="0. 1. 0."/>
    <limit lower="0." upper="1.3789309" effort="0." velocity="17453.2925199"/>
  </joint>
  <joint name="little_joint4" type="fixed">
    <origin xyz="-0.013709 0.0063957 0.024981 " rpy="0. 1.5707964 0. "/>
    <parent link="linker_hand_l20_left_isaac_sim_little_link3"/>
    <child link="linker_hand_l20_left_isaac_sim_little_link4"/>
  </joint>
  <joint name="middle_joint0" type="revolute">
    <origin xyz="-0.030599 -0.0050984 0.1587 " rpy="0. 0. 0."/>
    <parent link="hand_base_link"/>
    <child link="linker_hand_l20_left_isaac_sim_middle_link0"/>
    <axis xyz="1. 0. 0."/>
    <limit lower="0." upper="0.26" effort="100." velocity="0.9999999"/>
  </joint>
  <joint name="middle_joint1" type="revolute">
    <origin xyz="0.011115 -0.0047959 0. " rpy="0. 0. 0."/>
    <parent link="linker_hand_l20_left_isaac_sim_middle_link0"/>
    <child link="linker_hand_l20_left_isaac_sim_middle_link1"/>
    <axis xyz="0. 1. 0."/>
    <limit lower="0." upper="1.3999999" effort="100." velocity="0.9999999"/>
  </joint>
  <joint name="middle_joint2" type="revolute">
    <origin xyz="-0.0034454 0.0010465 0.044883 " rpy="0. 0. 0."/>
    <parent link="linker_hand_l20_left_isaac_sim_middle_link1"/>
    <child link="linker_hand_l20_left_isaac_sim_middle_link2"/>
    <axis xyz="0. 1. 0."/>
    <limit lower="0." upper="1.08" effort="100." velocity="0.9999999"/>
  </joint>
  <joint name="middle_joint3" type="revolute">
    <origin xyz="0.0084126 -0.0012 0.03069 " rpy="0. 0. 0."/>
    <parent link="linker_hand_l20_left_isaac_sim_middle_link2"/>
    <child link="linker_hand_l20_left_isaac_sim_middle_link3"/>
    <axis xyz="0. 1. 0."/>
    <limit lower="0." upper="1.3789309" effort="0." velocity="17453.2925199"/>
  </joint>
  <joint name="middle_joint4" type="fixed">
    <origin xyz="-0.013709 0.0063957 0.024981 " rpy="0. 1.5707964 0. "/>
    <parent link="linker_hand_l20_left_isaac_sim_middle_link3"/>
    <child link="linker_hand_l20_left_isaac_sim_middle_link4"/>
  </joint>
  <joint name="ring_joint0" type="revolute">
    <origin xyz="-0.028294 0.016502 0.15421 " rpy="0. 0. 0."/>
    <parent link="hand_base_link"/>
    <child link="linker_hand_l20_left_isaac_sim_ring_link0"/>
    <axis xyz="1. 0. 0."/>
    <limit lower="0." upper="0.26" effort="100." velocity="0.9999999"/>
  </joint>
  <joint name="ring_joint1" type="revolute">
    <origin xyz="0.011115 -0.0047959 0. " rpy="0. 0. 0."/>
    <parent link="linker_hand_l20_left_isaac_sim_ring_link0"/>
    <child link="linker_hand_l20_left_isaac_sim_ring_link1"/>
    <axis xyz="0. 1. 0."/>
    <limit lower="0." upper="1.3999999" effort="100." velocity="0.9999999"/>
  </joint>
  <joint name="ring_joint2" type="revolute">
    <origin xyz="-0.0034454 0.0010465 0.044883 " rpy="0. 0. 0."/>
    <parent link="linker_hand_l20_left_isaac_sim_ring_link1"/>
    <child link="linker_hand_l20_left_isaac_sim_ring_link2"/>
    <axis xyz="0. 1. 0."/>
    <limit lower="0." upper="1.08" effort="100." velocity="0.9999999"/>
  </joint>
  <joint name="ring_joint3" type="revolute">
    <origin xyz="0.0084126 -0.0012 0.03069 " rpy="0. 0. 0."/>
    <parent link="linker_hand_l20_left_isaac_sim_ring_link2"/>
    <child link="linker_hand_l20_left_isaac_sim_ring_link3"/>
    <axis xyz="0. 1. 0."/>
    <limit lower="0." upper="1.3789309" effort="0." velocity="17453.2925199"/>
  </joint>
  <joint name="ring_joint4" type="fixed">
    <origin xyz="-0.013709 0.0063957 0.024981 " rpy="0. 1.5707964 0. "/>
    <parent link="linker_hand_l20_left_isaac_sim_ring_link3"/>
    <child link="linker_hand_l20_left_isaac_sim_ring_link4"/>
  </joint>
  <joint name="root_joint" type="fixed">
    <origin xyz="0. 0. 0." rpy="0. 0. 0."/>
    <parent link="UF_ROBOT"/>
    <child link="world"/>
  </joint>
  <joint name="thumb_joint0" type="revolute">
    <origin xyz="-0.0025188 -0.0050821 0.052292 " rpy="0. 0. 3.1415927"/>
    <parent link="hand_base_link"/>
    <child link="linker_hand_l20_left_isaac_sim_thumb_link0"/>
    <axis xyz="1. 0. 0."/>
    <limit lower="-0.297" upper="0.683" effort="100." velocity="0.9999999"/>
  </joint>
  <joint name="thumb_joint1" type="revolute">
    <origin xyz="-0.024508 0.0008333 -0.00845 " rpy="0. 0. -3.1415927"/>
    <parent link="linker_hand_l20_left_isaac_sim_thumb_link0"/>
    <child link="linker_hand_l20_left_isaac_sim_thumb_link1"/>
    <axis xyz="0. 0. 1."/>
    <limit lower="0.122" upper="1.7799999" effort="100." velocity="0.9999999"/>
  </joint>
  <joint name="thumb_joint2" type="revolute">
    <origin xyz="0.010985 -0.030795 0.012414" rpy="0. 0. 3.1415927"/>
    <parent link="linker_hand_l20_left_isaac_sim_thumb_link1"/>
    <child link="linker_hand_l20_left_isaac_sim_thumb_link2"/>
    <axis xyz="1. 0. 0."/>
    <limit lower="0." upper="0.8699999" effort="100." velocity="0.9999999"/>
  </joint>
  <joint name="thumb_joint3" type="revolute">
    <origin xyz="0.0010999 0.044701 0.034112 " rpy="0. 0. 0."/>
    <parent link="linker_hand_l20_left_isaac_sim_thumb_link2"/>
    <child link="linker_hand_l20_left_isaac_sim_thumb_link3"/>
    <axis xyz="1. 0. 0."/>
    <limit lower="0." upper="1.2899999" effort="100." velocity="0.9999999"/>
  </joint>
  <joint name="thumb_joint4" type="revolute">
    <origin xyz="0.01277 0.030981 0.015322" rpy="0. 0. 0."/>
    <parent link="linker_hand_l20_left_isaac_sim_thumb_link3"/>
    <child link="linker_hand_l20_left_isaac_sim_thumb_link4"/>
    <axis xyz="1. 0. 0."/>
    <limit lower="-0.258" upper="1.5479999" effort="0." velocity="17453.2925199"/>
  </joint>
  <joint name="thumb_joint5" type="fixed">
    <origin xyz="-0.0040254 0.030887 0.0073227" rpy="-3.1415927 1.5707964 0. "/>
    <parent link="linker_hand_l20_left_isaac_sim_thumb_link4"/>
    <child link="linker_hand_l20_left_isaac_sim_thumb_link5"/>
  </joint>
  <link name="UF_ROBOT"/>
  <link name="UF_ROBOT_link1">
    <inertial>
      <origin xyz="-0.0002 0.02905 -0.01233" rpy="0. 0. 0."/>
      <mass value="2.382"/>
      <inertia ixx="0.0056905" ixy="-0.0000158" ixz="0.0000051" iyy="0.0049566" iyz="-0.0008734" izz="0.0033167"/>
    </inertial>
    <visual>
      <origin xyz="0. 0. 0." rpy="1.5707872 0. 0. "/>
      <geometry>
        <mesh filename="./meshes/UF_ROBOT_link1_visuals_link1_mesh.obj" scale="1. 1. 1."/>
      </geometry>
    </visual>
    <visual>
      <origin xyz="0. 0. 0." rpy="0. 0. 0."/>
      <geometry>
        <mesh filename="./meshes/UF_ROBOT_link1_collisions_link1_mesh.obj" scale="1. 1. 1."/>
      </geometry>
    </visual>
    <collision>
      <origin xyz="0. 0. 0." rpy="0. 0. 0."/>
      <geometry>
        <mesh filename="./meshes/UF_ROBOT_link1_collisions_link1_mesh.obj" scale="1. 1. 1."/>
      </geometry>
    </collision>
  </link>
  <link name="UF_ROBOT_link2">
    <inertial>
      <origin xyz="0.00022 -0.12856 0.01735" rpy="0. 0. 0."/>
      <mass value="1.869"/>
      <inertia ixx="0.0095989" ixy="0.0000015" ixz="0.0000056" iyy="0.0038247" iyz="-0.0031716" izz="0.0075657"/>
    </inertial>
    <visual>
      <origin xyz="0. 0. 0." rpy="1.5707873 0. 0. "/>
      <geometry>
        <mesh filename="./meshes/UF_ROBOT_link2_visuals_link2_mesh.obj" scale="1. 1. 1."/>
      </geometry>
    </visual>
    <visual>
      <origin xyz="0. 0. 0." rpy="0.0000001 0. 0. "/>
      <geometry>
        <mesh filename="./meshes/UF_ROBOT_link2_collisions_link2_mesh.obj" scale="1. 1. 1."/>
      </geometry>
    </visual>
    <collision>
      <origin xyz="0. 0. 0." rpy="0.0000001 0. 0. "/>
      <geometry>
        <mesh filename="./meshes/UF_ROBOT_link2_collisions_link2_mesh.obj" scale="1. 1. 1."/>
      </geometry>
    </collision>
  </link>
  <link name="UF_ROBOT_link3">
    <inertial>
      <origin xyz="0.0466 -0.02463 -0.00768" rpy="0. 0. 0."/>
      <mass value="1.6382999"/>
      <inertia ixx="0.0031096" ixy="0.0003084" ixz="-0.0005845" iyy="0.0026448" iyz="0.0003389" izz="0.0026624"/>
    </inertial>
    <visual>
      <origin xyz="0. 0. 0." rpy="1.5707872 0. 0. "/>
      <geometry>
        <mesh filename="./meshes/UF_ROBOT_link3_visuals_link3_mesh.obj" scale="1. 1. 1."/>
      </geometry>
    </visual>
    <visual>
      <origin xyz="0. 0. 0." rpy="-0.0000001 0. 0. "/>
      <geometry>
        <mesh filename="./meshes/UF_ROBOT_link3_collisions_link3_mesh.obj" scale="1. 1. 1."/>
      </geometry>
    </visual>
    <collision>
      <origin xyz="0. 0. 0." rpy="-0.0000001 0. 0. "/>
      <geometry>
        <mesh filename="./meshes/UF_ROBOT_link3_collisions_link3_mesh.obj" scale="1. 1. 1."/>
      </geometry>
    </collision>
  </link>
  <link name="UF_ROBOT_link4">
    <inertial>
      <origin xyz="0.07047 -0.11575 0.012 " rpy="0. 0. 0."/>
      <mass value="1.7269"/>
      <inertia ixx="0.005889" ixy="0.0013711" ixz="0.0008814" iyy="0.003597" iyz="-0.0017622" izz="0.0054324"/>
    </inertial>
    <visual>
      <origin xyz="0. 0. 0." rpy="1.5707872 0. 0. "/>
      <geometry>
        <mesh filename="./meshes/UF_ROBOT_link4_visuals_link4_mesh.obj" scale="1. 1. 1."/>
      </geometry>
    </visual>
    <visual>
      <origin xyz="0. 0. 0." rpy="-0.0000001 0. 0. "/>
      <geometry>
        <mesh filename="./meshes/UF_ROBOT_link4_collisions_link4_mesh.obj" scale="1. 1. 1."/>
      </geometry>
    </visual>
    <collision>
      <origin xyz="0. 0. 0." rpy="-0.0000001 0. 0. "/>
      <geometry>
        <mesh filename="./meshes/UF_ROBOT_link4_collisions_link4_mesh.obj" scale="1. 1. 1."/>
      </geometry>
    </collision>
  </link>
  <link name="UF_ROBOT_link5">
    <inertial>
      <origin xyz="-0.00032 0.01604 -0.026 " rpy="0. 0. 0."/>
      <mass value="1.3203"/>
      <inertia ixx="0.0053467" ixy="0.0000151" ixz="-0.0000004" iyy="0.0049779" iyz="-0.0002213" izz="0.0013624"/>
    </inertial>
    <visual>
      <origin xyz="0. -0. 0." rpy="1.5707873 0. 0. "/>
      <geometry>
        <mesh filename="./meshes/UF_ROBOT_link5_visuals_link5_mesh.obj" scale="1. 1. 1."/>
      </geometry>
    </visual>
    <visual>
      <origin xyz="0. -0. 0." rpy="0.0000001 0. 0. "/>
      <geometry>
        <mesh filename="./meshes/UF_ROBOT_link5_collisions_link5_mesh.obj" scale="1. 1. 1."/>
      </geometry>
    </visual>
    <collision>
      <origin xyz="0. -0. 0." rpy="0.0000001 0. 0. "/>
      <geometry>
        <mesh filename="./meshes/UF_ROBOT_link5_collisions_link5_mesh.obj" scale="1. 1. 1."/>
      </geometry>
    </collision>
  </link>
  <link name="UF_ROBOT_link6">
    <inertial>
      <origin xyz="0.06469 0.03278 0.02141" rpy="0. 0. 0."/>
      <mass value="1.325"/>
      <inertia ixx="0.0014745" ixy="-0.000488" ixz="0.0002953" iyy="0.0019037" iyz="0.0001475" izz="0.0023652"/>
    </inertial>
    <visual>
      <origin xyz="0. 0. 0." rpy="1.5707872 0. 0. "/>
      <geometry>
        <mesh filename="./meshes/UF_ROBOT_link6_visuals_link6_mesh.obj" scale="1. 1. 1."/>
      </geometry>
    </visual>
    <visual>
      <origin xyz="0. 0. 0." rpy="0. 0. 0."/>
      <geometry>
        <mesh filename="./meshes/UF_ROBOT_link6_collisions_link6_mesh.obj" scale="1. 1. 1."/>
      </geometry>
    </visual>
    <collision>
      <origin xyz="0. 0. 0." rpy="0. 0. 0."/>
      <geometry>
        <mesh filename="./meshes/UF_ROBOT_link6_collisions_link6_mesh.obj" scale="1. 1. 1."/>
      </geometry>
    </collision>
  </link>
  <link name="UF_ROBOT_link7">
    <inertial>
      <origin xyz="0. -0.00677 -0.01098" rpy="0. 0. 0."/>
      <mass value="0.17"/>
      <inertia ixx="0.000093" ixy="0." ixz="0." iyy="0.0000587" iyz="-0.0000036" izz="0.000132"/>
    </inertial>
    <visual>
      <origin xyz="0. -0. 0." rpy="1.5707872 0. 0. "/>
      <geometry>
        <mesh filename="./meshes/UF_ROBOT_link7_visuals_link7_mesh.obj" scale="1. 1. 1."/>
      </geometry>
    </visual>
    <visual>
      <origin xyz="0. -0. 0." rpy="-0. 0. 0."/>
      <geometry>
        <mesh filename="./meshes/end_tool_mesh.obj" scale="1. 1. 1."/>
      </geometry>
    </visual>
    <collision>
      <origin xyz="0. -0. 0." rpy="-0. 0. 0."/>
      <geometry>
        <mesh filename="./meshes/end_tool_mesh.obj" scale="1. 1. 1."/>
      </geometry>
    </collision>
  </link>
  <link name="hand_base_link">
    <inertial>
      <origin xyz="-0.010282 0.0035264 0.0845625" rpy="0. 0. 0."/>
      <mass value="0.11652"/>
      <inertia ixx="0.0001994" ixy="-0.0000007" ixz="0.0000095" iyy="0.0001172" iyz="0.000001" izz="0.0001086"/>
    </inertial>
    <visual>
      <origin xyz="0. 0. 0." rpy="0. 0. 0."/>
      <geometry>
        <mesh filename="./meshes/hand_base_link_visuals_base_link_node_STL_BINARY__mesh.obj" scale="1. 1. 1."/>
      </geometry>
    </visual>
    <visual>
      <origin xyz="0. 0. 0." rpy="0. 0. 0."/>
      <geometry>
        <mesh filename="./meshes/hand_base_link_collisions_base_link_node_STL_BINARY__mesh.obj" scale="1. 1. 1."/>
      </geometry>
    </visual>
    <collision>
      <origin xyz="0. 0. 0." rpy="0. 0. 0."/>
      <geometry>
        <mesh filename="./meshes/hand_base_link_collisions_base_link_node_STL_BINARY__mesh.obj" scale="1. 1. 1."/>
      </geometry>
    </collision>
  </link>
  <link name="linker_hand_base"/>
  <link name="linker_hand_l20_left_isaac_sim_index_link0">
    <inertial>
      <origin xyz="0.0058243 0.0000006 0.0022475" rpy="0. 0. 0."/>
      <mass value="0.0008588"/>
      <inertia ixx="0." ixy="-0." ixz="-0." iyy="0." iyz="-0." izz="0."/>
    </inertial>
    <visual>
      <origin xyz="0. 0. 0." rpy="0. 0. 0."/>
      <geometry>
        <mesh filename="./meshes/linker_hand_l20_left_isaac_sim_index_link0_visuals_index_link0_node_STL_BINARY__mesh.obj" scale="1. 1. 1."/>
      </geometry>
    </visual>
    <visual>
      <origin xyz="0. 0. 0." rpy="0. 0. 0."/>
      <geometry>
        <mesh filename="./meshes/linker_hand_l20_left_isaac_sim_index_link0_collisions_index_link0_node_STL_BINARY__mesh.obj" scale="1. 1. 1."/>
      </geometry>
    </visual>
    <collision>
      <origin xyz="0. 0. 0." rpy="0. 0. 0."/>
      <geometry>
        <mesh filename="./meshes/linker_hand_l20_left_isaac_sim_index_link0_collisions_index_link0_node_STL_BINARY__mesh.obj" scale="1. 1. 1."/>
      </geometry>
    </collision>
  </link>
  <link name="linker_hand_l20_left_isaac_sim_index_link1">
    <inertial>
      <origin xyz="-0.0006834 0.0048078 0.0243018" rpy="0. 0. 0."/>
      <mass value="0.0045848"/>
      <inertia ixx="0.0000007" ixy="0." ixz="0." iyy="0.0000007" iyz="0." izz="0.0000001"/>
    </inertial>
    <visual>
      <origin xyz="0. 0. 0." rpy="0. 0. 0."/>
      <geometry>
        <mesh filename="./meshes/linker_hand_l20_left_isaac_sim_index_link1_visuals_index_link1_node_STL_BINARY__mesh.obj" scale="1. 1. 1."/>
      </geometry>
    </visual>
    <visual>
      <origin xyz="0. 0. 0." rpy="0. 0. 0."/>
      <geometry>
        <mesh filename="./meshes/linker_hand_l20_left_isaac_sim_index_link1_collisions_index_link1_node_STL_BINARY__mesh.obj" scale="1. 1. 1."/>
      </geometry>
    </visual>
    <collision>
      <origin xyz="0. 0. 0." rpy="0. 0. 0."/>
      <geometry>
        <mesh filename="./meshes/linker_hand_l20_left_isaac_sim_index_link1_collisions_index_link1_node_STL_BINARY__mesh.obj" scale="1. 1. 1."/>
      </geometry>
    </collision>
  </link>
  <link name="linker_hand_l20_left_isaac_sim_index_link2">
    <inertial>
      <origin xyz="0.0028162 0.0038138 0.0165996" rpy="0. 0. 0."/>
      <mass value="0.0024094"/>
      <inertia ixx="0.0000002" ixy="-0." ixz="-0." iyy="0.0000002" iyz="0." izz="0.0000001"/>
    </inertial>
    <visual>
      <origin xyz="0. 0. 0." rpy="0. 0. 0."/>
      <geometry>
        <mesh filename="./meshes/linker_hand_l20_left_isaac_sim_index_link2_visuals_index_link2_node_STL_BINARY__mesh.obj" scale="1. 1. 1."/>
      </geometry>
    </visual>
    <visual>
      <origin xyz="0. 0. 0." rpy="0. 0. 0."/>
      <geometry>
        <mesh filename="./meshes/linker_hand_l20_left_isaac_sim_index_link2_collisions_index_link2_node_STL_BINARY__mesh.obj" scale="1. 1. 1."/>
      </geometry>
    </visual>
    <collision>
      <origin xyz="0. 0. 0." rpy="0. 0. 0."/>
      <geometry>
        <mesh filename="./meshes/linker_hand_l20_left_isaac_sim_index_link2_collisions_index_link2_node_STL_BINARY__mesh.obj" scale="1. 1. 1."/>
      </geometry>
    </collision>
  </link>
  <link name="linker_hand_l20_left_isaac_sim_index_link3">
    <inertial>
      <origin xyz="-0.0067751 0.0052086 0.0097167" rpy="0. 0. 0."/>
      <mass value="0.0035622"/>
      <inertia ixx="0.0000002" ixy="-0." ixz="0." iyy="0.0000002" iyz="0." izz="0.0000001"/>
    </inertial>
    <visual>
      <origin xyz="0. 0. 0." rpy="0. 0. 0."/>
      <geometry>
        <mesh filename="./meshes/linker_hand_l20_left_isaac_sim_index_link3_visuals_index_link3_node_STL_BINARY__mesh.obj" scale="1. 1. 1."/>
      </geometry>
    </visual>
    <visual>
      <origin xyz="0. 0. 0." rpy="0. 0. 0."/>
      <geometry>
        <mesh filename="./meshes/linker_hand_l20_left_isaac_sim_index_link3_collisions_index_link3_node_STL_BINARY__mesh.obj" scale="1. 1. 1."/>
      </geometry>
    </visual>
    <collision>
      <origin xyz="0. 0. 0." rpy="0. 0. 0."/>
      <geometry>
        <mesh filename="./meshes/linker_hand_l20_left_isaac_sim_index_link3_collisions_index_link3_node_STL_BINARY__mesh.obj" scale="1. 1. 1."/>
      </geometry>
    </collision>
  </link>
  <link name="linker_hand_l20_left_isaac_sim_index_link4">
    <inertial>
      <origin xyz="0. -0.001 0. " rpy="0. 0. 0."/>
      <mass value="0.0000016"/>
      <inertia ixx="0." ixy="0." ixz="0." iyy="0." iyz="0." izz="0."/>
    </inertial>
    <visual>
      <origin xyz="0. -0. 0." rpy="0. -1.5707964 0. "/>
      <geometry>
        <mesh filename="./meshes/linker_hand_l20_left_isaac_sim_index_link4_visuals_index_link4_node_STL_BINARY__mesh.obj" scale="1. 1. 1."/>
      </geometry>
    </visual>
    <visual>
      <origin xyz="0. -0. 0." rpy="0. -1.5707964 0. "/>
      <geometry>
        <mesh filename="./meshes/linker_hand_l20_left_isaac_sim_index_link4_collisions_index_link4_node_STL_BINARY__mesh.obj" scale="1. 1. 1."/>
      </geometry>
    </visual>
    <collision>
      <origin xyz="0. -0. 0." rpy="0. -1.5707964 0. "/>
      <geometry>
        <mesh filename="./meshes/linker_hand_l20_left_isaac_sim_index_link4_collisions_index_link4_node_STL_BINARY__mesh.obj" scale="1. 1. 1."/>
      </geometry>
    </collision>
  </link>
  <link name="linker_hand_l20_left_isaac_sim_little_link0">
    <inertial>
      <origin xyz="0.0058243 0.0000006 0.0022475" rpy="0. 0. 0."/>
      <mass value="0.0008588"/>
      <inertia ixx="0." ixy="-0." ixz="-0." iyy="0." iyz="-0." izz="0."/>
    </inertial>
    <visual>
      <origin xyz="0. 0. 0." rpy="0. 0. 0."/>
      <geometry>
        <mesh filename="./meshes/linker_hand_l20_left_isaac_sim_little_link0_visuals_little_link0_node_STL_BINARY__mesh.obj" scale="1. 1. 1."/>
      </geometry>
    </visual>
    <visual>
      <origin xyz="0. 0. 0." rpy="0. 0. 0."/>
      <geometry>
        <mesh filename="./meshes/linker_hand_l20_left_isaac_sim_little_link0_collisions_little_link0_node_STL_BINARY__mesh.obj" scale="1. 1. 1."/>
      </geometry>
    </visual>
    <collision>
      <origin xyz="0. 0. 0." rpy="0. 0. 0."/>
      <geometry>
        <mesh filename="./meshes/linker_hand_l20_left_isaac_sim_little_link0_collisions_little_link0_node_STL_BINARY__mesh.obj" scale="1. 1. 1."/>
      </geometry>
    </collision>
  </link>
  <link name="linker_hand_l20_left_isaac_sim_little_link1">
    <inertial>
      <origin xyz="-0.0006834 0.0048078 0.0243018" rpy="0. 0. 0."/>
      <mass value="0.0045848"/>
      <inertia ixx="0.0000007" ixy="0." ixz="0." iyy="0.0000007" iyz="0." izz="0.0000001"/>
    </inertial>
    <visual>
      <origin xyz="0. 0. 0." rpy="0. 0. 0."/>
      <geometry>
        <mesh filename="./meshes/linker_hand_l20_left_isaac_sim_little_link1_visuals_little_link1_node_STL_BINARY__mesh.obj" scale="1. 1. 1."/>
      </geometry>
    </visual>
    <visual>
      <origin xyz="0. 0. 0." rpy="0. 0. 0."/>
      <geometry>
        <mesh filename="./meshes/linker_hand_l20_left_isaac_sim_little_link1_collisions_little_link1_node_STL_BINARY__mesh.obj" scale="1. 1. 1."/>
      </geometry>
    </visual>
    <collision>
      <origin xyz="0. 0. 0." rpy="0. 0. 0."/>
      <geometry>
        <mesh filename="./meshes/linker_hand_l20_left_isaac_sim_little_link1_collisions_little_link1_node_STL_BINARY__mesh.obj" scale="1. 1. 1."/>
      </geometry>
    </collision>
  </link>
  <link name="linker_hand_l20_left_isaac_sim_little_link2">
    <inertial>
      <origin xyz="0.0028162 0.0038138 0.0165996" rpy="0. 0. 0."/>
      <mass value="0.0024094"/>
      <inertia ixx="0.0000002" ixy="-0." ixz="-0." iyy="0.0000002" iyz="0." izz="0.0000001"/>
    </inertial>
    <visual>
      <origin xyz="0. 0. 0." rpy="0. 0. 0."/>
      <geometry>
        <mesh filename="./meshes/linker_hand_l20_left_isaac_sim_little_link2_visuals_little_link2_node_STL_BINARY__mesh.obj" scale="1. 1. 1."/>
      </geometry>
    </visual>
    <visual>
      <origin xyz="0. 0. 0." rpy="0. 0. 0."/>
      <geometry>
        <mesh filename="./meshes/linker_hand_l20_left_isaac_sim_little_link2_collisions_little_link2_node_STL_BINARY__mesh.obj" scale="1. 1. 1."/>
      </geometry>
    </visual>
    <collision>
      <origin xyz="0. 0. 0." rpy="0. 0. 0."/>
      <geometry>
        <mesh filename="./meshes/linker_hand_l20_left_isaac_sim_little_link2_collisions_little_link2_node_STL_BINARY__mesh.obj" scale="1. 1. 1."/>
      </geometry>
    </collision>
  </link>
  <link name="linker_hand_l20_left_isaac_sim_little_link3">
    <inertial>
      <origin xyz="-0.0067751 0.0052086 0.0097167" rpy="0. 0. 0."/>
      <mass value="0.0035622"/>
      <inertia ixx="0.0000002" ixy="-0." ixz="0." iyy="0.0000002" iyz="0." izz="0.0000001"/>
    </inertial>
    <visual>
      <origin xyz="0. 0. 0." rpy="0. 0. 0."/>
      <geometry>
        <mesh filename="./meshes/linker_hand_l20_left_isaac_sim_little_link3_visuals_little_link3_node_STL_BINARY__mesh.obj" scale="1. 1. 1."/>
      </geometry>
    </visual>
    <visual>
      <origin xyz="0. 0. 0." rpy="0. 0. 0."/>
      <geometry>
        <mesh filename="./meshes/linker_hand_l20_left_isaac_sim_little_link3_collisions_little_link3_node_STL_BINARY__mesh.obj" scale="1. 1. 1."/>
      </geometry>
    </visual>
    <collision>
      <origin xyz="0. 0. 0." rpy="0. 0. 0."/>
      <geometry>
        <mesh filename="./meshes/linker_hand_l20_left_isaac_sim_little_link3_collisions_little_link3_node_STL_BINARY__mesh.obj" scale="1. 1. 1."/>
      </geometry>
    </collision>
  </link>
  <link name="linker_hand_l20_left_isaac_sim_little_link4">
    <inertial>
      <origin xyz="0. -0.001 0. " rpy="0. 0. 0."/>
      <mass value="0.0000016"/>
      <inertia ixx="0." ixy="0." ixz="0." iyy="0." iyz="0." izz="0."/>
    </inertial>
    <visual>
      <origin xyz="0. 0. -0." rpy="0. -1.5707964 0. "/>
      <geometry>
        <mesh filename="./meshes/linker_hand_l20_left_isaac_sim_little_link4_visuals_little_link4_node_STL_BINARY__mesh.obj" scale="1. 1. 1."/>
      </geometry>
    </visual>
    <visual>
      <origin xyz="0. 0. -0." rpy="0. -1.5707964 0. "/>
      <geometry>
        <mesh filename="./meshes/linker_hand_l20_left_isaac_sim_little_link4_collisions_little_link4_node_STL_BINARY__mesh.obj" scale="1. 1. 1."/>
      </geometry>
    </visual>
    <collision>
      <origin xyz="0. 0. -0." rpy="0. -1.5707964 0. "/>
      <geometry>
        <mesh filename="./meshes/linker_hand_l20_left_isaac_sim_little_link4_collisions_little_link4_node_STL_BINARY__mesh.obj" scale="1. 1. 1."/>
      </geometry>
    </collision>
  </link>
  <link name="linker_hand_l20_left_isaac_sim_middle_link0">
    <inertial>
      <origin xyz="0.0058243 0.0000006 0.0022475" rpy="0. 0. 0."/>
      <mass value="0.0008588"/>
      <inertia ixx="0." ixy="-0." ixz="-0." iyy="0." iyz="-0." izz="0."/>
    </inertial>
    <visual>
      <origin xyz="0. 0. 0." rpy="0. 0. 0."/>
      <geometry>
        <mesh filename="./meshes/linker_hand_l20_left_isaac_sim_middle_link0_visuals_middle_link0_node_STL_BINARY__mesh.obj" scale="1. 1. 1."/>
      </geometry>
    </visual>
    <visual>
      <origin xyz="0. 0. 0." rpy="0. 0. 0."/>
      <geometry>
        <mesh filename="./meshes/linker_hand_l20_left_isaac_sim_middle_link0_collisions_middle_link0_node_STL_BINARY__mesh.obj" scale="1. 1. 1."/>
      </geometry>
    </visual>
    <collision>
      <origin xyz="0. 0. 0." rpy="0. 0. 0."/>
      <geometry>
        <mesh filename="./meshes/linker_hand_l20_left_isaac_sim_middle_link0_collisions_middle_link0_node_STL_BINARY__mesh.obj" scale="1. 1. 1."/>
      </geometry>
    </collision>
  </link>
  <link name="linker_hand_l20_left_isaac_sim_middle_link1">
    <inertial>
      <origin xyz="-0.0006834 0.0048078 0.0243018" rpy="0. 0. 0."/>
      <mass value="0.0045848"/>
      <inertia ixx="0.0000007" ixy="0." ixz="0." iyy="0.0000007" iyz="0." izz="0.0000001"/>
    </inertial>
    <visual>
      <origin xyz="0. 0. 0." rpy="0. 0. 0."/>
      <geometry>
        <mesh filename="./meshes/linker_hand_l20_left_isaac_sim_middle_link1_visuals_middle_link1_node_STL_BINARY__mesh.obj" scale="1. 1. 1."/>
      </geometry>
    </visual>
    <visual>
      <origin xyz="0. 0. 0." rpy="0. 0. 0."/>
      <geometry>
        <mesh filename="./meshes/linker_hand_l20_left_isaac_sim_middle_link1_collisions_middle_link1_node_STL_BINARY__mesh.obj" scale="1. 1. 1."/>
      </geometry>
    </visual>
    <collision>
      <origin xyz="0. 0. 0." rpy="0. 0. 0."/>
      <geometry>
        <mesh filename="./meshes/linker_hand_l20_left_isaac_sim_middle_link1_collisions_middle_link1_node_STL_BINARY__mesh.obj" scale="1. 1. 1."/>
      </geometry>
    </collision>
  </link>
  <link name="linker_hand_l20_left_isaac_sim_middle_link2">
    <inertial>
      <origin xyz="0.0028162 0.0038138 0.0165996" rpy="0. 0. 0."/>
      <mass value="0.0024094"/>
      <inertia ixx="0.0000002" ixy="-0." ixz="-0." iyy="0.0000002" iyz="0." izz="0.0000001"/>
    </inertial>
    <visual>
      <origin xyz="0. 0. 0." rpy="0. 0. 0."/>
      <geometry>
        <mesh filename="./meshes/linker_hand_l20_left_isaac_sim_middle_link2_visuals_middle_link2_node_STL_BINARY__mesh.obj" scale="1. 1. 1."/>
      </geometry>
    </visual>
    <visual>
      <origin xyz="0. 0. 0." rpy="0. 0. 0."/>
      <geometry>
        <mesh filename="./meshes/linker_hand_l20_left_isaac_sim_middle_link2_collisions_middle_link2_node_STL_BINARY__mesh.obj" scale="1. 1. 1."/>
      </geometry>
    </visual>
    <collision>
      <origin xyz="0. 0. 0." rpy="0. 0. 0."/>
      <geometry>
        <mesh filename="./meshes/linker_hand_l20_left_isaac_sim_middle_link2_collisions_middle_link2_node_STL_BINARY__mesh.obj" scale="1. 1. 1."/>
      </geometry>
    </collision>
  </link>
  <link name="linker_hand_l20_left_isaac_sim_middle_link3">
    <inertial>
      <origin xyz="-0.0067751 0.0052086 0.0097167" rpy="0. 0. 0."/>
      <mass value="0.0035622"/>
      <inertia ixx="0.0000002" ixy="-0." ixz="0." iyy="0.0000002" iyz="0." izz="0.0000001"/>
    </inertial>
    <visual>
      <origin xyz="0. 0. 0." rpy="0. 0. 0."/>
      <geometry>
        <mesh filename="./meshes/linker_hand_l20_left_isaac_sim_middle_link3_visuals_middle_link3_node_STL_BINARY__mesh.obj" scale="1. 1. 1."/>
      </geometry>
    </visual>
    <visual>
      <origin xyz="0. 0. 0." rpy="0. 0. 0."/>
      <geometry>
        <mesh filename="./meshes/linker_hand_l20_left_isaac_sim_middle_link3_collisions_middle_link3_node_STL_BINARY__mesh.obj" scale="1. 1. 1."/>
      </geometry>
    </visual>
    <collision>
      <origin xyz="0. 0. 0." rpy="0. 0. 0."/>
      <geometry>
        <mesh filename="./meshes/linker_hand_l20_left_isaac_sim_middle_link3_collisions_middle_link3_node_STL_BINARY__mesh.obj" scale="1. 1. 1."/>
      </geometry>
    </collision>
  </link>
  <link name="linker_hand_l20_left_isaac_sim_middle_link4">
    <inertial>
      <origin xyz="0. -0.001 0. " rpy="0. 0. 0."/>
      <mass value="0.0000016"/>
      <inertia ixx="0." ixy="0." ixz="0." iyy="0." iyz="0." izz="0."/>
    </inertial>
    <visual>
      <origin xyz="-0. 0. -0." rpy="0. -1.5707964 0. "/>
      <geometry>
        <mesh filename="./meshes/linker_hand_l20_left_isaac_sim_middle_link4_visuals_middle_link4_node_STL_BINARY__mesh.obj" scale="1. 1. 1."/>
      </geometry>
    </visual>
    <visual>
      <origin xyz="-0. 0. -0." rpy="0. -1.5707964 0. "/>
      <geometry>
        <mesh filename="./meshes/linker_hand_l20_left_isaac_sim_middle_link4_collisions_middle_link4_node_STL_BINARY__mesh.obj" scale="1. 1. 1."/>
      </geometry>
    </visual>
    <collision>
      <origin xyz="-0. 0. -0." rpy="0. -1.5707964 0. "/>
      <geometry>
        <mesh filename="./meshes/linker_hand_l20_left_isaac_sim_middle_link4_collisions_middle_link4_node_STL_BINARY__mesh.obj" scale="1. 1. 1."/>
      </geometry>
    </collision>
  </link>
  <link name="linker_hand_l20_left_isaac_sim_ring_link0">
    <inertial>
      <origin xyz="0.0058243 0.0000006 0.0022475" rpy="0. 0. 0."/>
      <mass value="0.0008588"/>
      <inertia ixx="0." ixy="-0." ixz="-0." iyy="0." iyz="-0." izz="0."/>
    </inertial>
    <visual>
      <origin xyz="0. 0. 0." rpy="0. 0. 0."/>
      <geometry>
        <mesh filename="./meshes/linker_hand_l20_left_isaac_sim_ring_link0_visuals_ring_link0_node_STL_BINARY__mesh.obj" scale="1. 1. 1."/>
      </geometry>
    </visual>
    <visual>
      <origin xyz="0. 0. 0." rpy="0. 0. 0."/>
      <geometry>
        <mesh filename="./meshes/linker_hand_l20_left_isaac_sim_ring_link0_collisions_ring_link0_node_STL_BINARY__mesh.obj" scale="1. 1. 1."/>
      </geometry>
    </visual>
    <collision>
      <origin xyz="0. 0. 0." rpy="0. 0. 0."/>
      <geometry>
        <mesh filename="./meshes/linker_hand_l20_left_isaac_sim_ring_link0_collisions_ring_link0_node_STL_BINARY__mesh.obj" scale="1. 1. 1."/>
      </geometry>
    </collision>
  </link>
  <link name="linker_hand_l20_left_isaac_sim_ring_link1">
    <inertial>
      <origin xyz="-0.0006834 0.0048078 0.0243018" rpy="0. 0. 0."/>
      <mass value="0.0045848"/>
      <inertia ixx="0.0000007" ixy="0." ixz="0." iyy="0.0000007" iyz="0." izz="0.0000001"/>
    </inertial>
    <visual>
      <origin xyz="0. 0. 0." rpy="0. 0. 0."/>
      <geometry>
        <mesh filename="./meshes/linker_hand_l20_left_isaac_sim_ring_link1_visuals_ring_link1_node_STL_BINARY__mesh.obj" scale="1. 1. 1."/>
      </geometry>
    </visual>
    <visual>
      <origin xyz="0. 0. 0." rpy="0. 0. 0."/>
      <geometry>
        <mesh filename="./meshes/linker_hand_l20_left_isaac_sim_ring_link1_collisions_ring_link1_node_STL_BINARY__mesh.obj" scale="1. 1. 1."/>
      </geometry>
    </visual>
    <collision>
      <origin xyz="0. 0. 0." rpy="0. 0. 0."/>
      <geometry>
        <mesh filename="./meshes/linker_hand_l20_left_isaac_sim_ring_link1_collisions_ring_link1_node_STL_BINARY__mesh.obj" scale="1. 1. 1."/>
      </geometry>
    </collision>
  </link>
  <link name="linker_hand_l20_left_isaac_sim_ring_link2">
    <inertial>
      <origin xyz="0.0028162 0.0038138 0.0165996" rpy="0. 0. 0."/>
      <mass value="0.0024094"/>
      <inertia ixx="0.0000002" ixy="-0." ixz="-0." iyy="0.0000002" iyz="0." izz="0.0000001"/>
    </inertial>
    <visual>
      <origin xyz="0. 0. 0." rpy="0. 0. 0."/>
      <geometry>
        <mesh filename="./meshes/linker_hand_l20_left_isaac_sim_ring_link2_visuals_ring_link2_node_STL_BINARY__mesh.obj" scale="1. 1. 1."/>
      </geometry>
    </visual>
    <visual>
      <origin xyz="0. 0. 0." rpy="0. 0. 0."/>
      <geometry>
        <mesh filename="./meshes/linker_hand_l20_left_isaac_sim_ring_link2_collisions_ring_link2_node_STL_BINARY__mesh.obj" scale="1. 1. 1."/>
      </geometry>
    </visual>
    <collision>
      <origin xyz="0. 0. 0." rpy="0. 0. 0."/>
      <geometry>
        <mesh filename="./meshes/linker_hand_l20_left_isaac_sim_ring_link2_collisions_ring_link2_node_STL_BINARY__mesh.obj" scale="1. 1. 1."/>
      </geometry>
    </collision>
  </link>
  <link name="linker_hand_l20_left_isaac_sim_ring_link3">
    <inertial>
      <origin xyz="-0.0067751 0.0052086 0.0097167" rpy="0. 0. 0."/>
      <mass value="0.0035622"/>
      <inertia ixx="0.0000002" ixy="-0." ixz="0." iyy="0.0000002" iyz="0." izz="0.0000001"/>
    </inertial>
    <visual>
      <origin xyz="0. 0. 0." rpy="0. 0. 0."/>
      <geometry>
        <mesh filename="./meshes/linker_hand_l20_left_isaac_sim_ring_link3_visuals_ring_link3_node_STL_BINARY__mesh.obj" scale="1. 1. 1."/>
      </geometry>
    </visual>
    <visual>
      <origin xyz="0. 0. 0." rpy="0. 0. 0."/>
      <geometry>
        <mesh filename="./meshes/linker_hand_l20_left_isaac_sim_ring_link3_collisions_ring_link3_node_STL_BINARY__mesh.obj" scale="1. 1. 1."/>
      </geometry>
    </visual>
    <collision>
      <origin xyz="0. 0. 0." rpy="0. 0. 0."/>
      <geometry>
        <mesh filename="./meshes/linker_hand_l20_left_isaac_sim_ring_link3_collisions_ring_link3_node_STL_BINARY__mesh.obj" scale="1. 1. 1."/>
      </geometry>
    </collision>
  </link>
  <link name="linker_hand_l20_left_isaac_sim_ring_link4">
    <inertial>
      <origin xyz="0. -0.001 0. " rpy="0. 0. 0."/>
      <mass value="0.0000016"/>
      <inertia ixx="0." ixy="0." ixz="0." iyy="0." iyz="0." izz="0."/>
    </inertial>
    <visual>
      <origin xyz="0. 0. 0." rpy="0. -1.5707964 0. "/>
      <geometry>
        <mesh filename="./meshes/linker_hand_l20_left_isaac_sim_ring_link4_visuals_ring_link4_node_STL_BINARY__mesh.obj" scale="1. 1. 1."/>
      </geometry>
    </visual>
    <visual>
      <origin xyz="0. 0. 0." rpy="0. -1.5707964 0. "/>
      <geometry>
        <mesh filename="./meshes/linker_hand_l20_left_isaac_sim_ring_link4_collisions_ring_link4_node_STL_BINARY__mesh.obj" scale="1. 1. 1."/>
      </geometry>
    </visual>
    <collision>
      <origin xyz="0. 0. 0." rpy="0. -1.5707964 0. "/>
      <geometry>
        <mesh filename="./meshes/linker_hand_l20_left_isaac_sim_ring_link4_collisions_ring_link4_node_STL_BINARY__mesh.obj" scale="1. 1. 1."/>
      </geometry>
    </collision>
  </link>
  <link name="linker_hand_l20_left_isaac_sim_thumb_link0">
    <inertial>
      <origin xyz="0.0127888 -0.0025056 0.0016311" rpy="0. 0. 0."/>
      <mass value="0.002748"/>
      <inertia ixx="0.0000003" ixy="0." ixz="-0." iyy="0.0000001" iyz="0." izz="0.0000003"/>
    </inertial>
    <visual>
      <origin xyz="0. 0. 0." rpy="0. 0. -3.1415927"/>
      <geometry>
        <mesh filename="./meshes/linker_hand_l20_left_isaac_sim_thumb_link0_visuals_thumb_link0_node_STL_BINARY__mesh.obj" scale="1. 1. 1."/>
      </geometry>
    </visual>
    <visual>
      <origin xyz="0. 0. 0." rpy="0. 0. -3.1415927"/>
      <geometry>
        <mesh filename="./meshes/linker_hand_l20_left_isaac_sim_thumb_link0_collisions_thumb_link0_node_STL_BINARY__mesh.obj" scale="1. 1. 1."/>
      </geometry>
    </visual>
    <collision>
      <origin xyz="0. 0. 0." rpy="0. 0. -3.1415927"/>
      <geometry>
        <mesh filename="./meshes/linker_hand_l20_left_isaac_sim_thumb_link0_collisions_thumb_link0_node_STL_BINARY__mesh.obj" scale="1. 1. 1."/>
      </geometry>
    </collision>
  </link>
  <link name="linker_hand_l20_left_isaac_sim_thumb_link1">
    <inertial>
      <origin xyz="-0.001065 -0.0129271 0.0095589" rpy="0. 0. 0."/>
      <mass value="0.0018808"/>
      <inertia ixx="0.0000003" ixy="0." ixz="-0." iyy="0.0000001" iyz="0.0000001" izz="0.0000003"/>
    </inertial>
    <visual>
      <origin xyz="0. 0. 0." rpy="0. 0. 0."/>
      <geometry>
        <mesh filename="./meshes/linker_hand_l20_left_isaac_sim_thumb_link1_visuals_thumb_link1_node_STL_BINARY__mesh.obj" scale="1. 1. 1."/>
      </geometry>
    </visual>
    <visual>
      <origin xyz="0. 0. 0." rpy="0. 0. 0."/>
      <geometry>
        <mesh filename="./meshes/linker_hand_l20_left_isaac_sim_thumb_link1_collisions_thumb_link1_node_STL_BINARY__mesh.obj" scale="1. 1. 1."/>
      </geometry>
    </visual>
    <collision>
      <origin xyz="0. 0. 0." rpy="0. 0. 0."/>
      <geometry>
        <mesh filename="./meshes/linker_hand_l20_left_isaac_sim_thumb_link1_collisions_thumb_link1_node_STL_BINARY__mesh.obj" scale="1. 1. 1."/>
      </geometry>
    </collision>
  </link>
  <link name="linker_hand_l20_left_isaac_sim_thumb_link2">
    <inertial>
      <origin xyz="-0.0106242 -0.0208034 0.0161575" rpy="0. 0. 0."/>
      <mass value="0.0205071"/>
      <inertia ixx="0.0000085" ixy="0.0000001" ixz="-0." iyy="0.0000036" iyz="0.0000027" izz="0.0000058"/>
    </inertial>
    <visual>
      <origin xyz="0. -0. 0." rpy="0. 0. -3.1415927"/>
      <geometry>
        <mesh filename="./meshes/linker_hand_l20_left_isaac_sim_thumb_link2_visuals_thumb_link2_node_STL_BINARY__mesh.obj" scale="1. 1. 1."/>
      </geometry>
    </visual>
    <visual>
      <origin xyz="0. -0. 0." rpy="0. 0. -3.1415927"/>
      <geometry>
        <mesh filename="./meshes/linker_hand_l20_left_isaac_sim_thumb_link2_collisions_thumb_link2_node_STL_BINARY__mesh.obj" scale="1. 1. 1."/>
      </geometry>
    </visual>
    <collision>
      <origin xyz="0. -0. 0." rpy="0. 0. -3.1415927"/>
      <geometry>
        <mesh filename="./meshes/linker_hand_l20_left_isaac_sim_thumb_link2_collisions_thumb_link2_node_STL_BINARY__mesh.obj" scale="1. 1. 1."/>
      </geometry>
    </collision>
  </link>
  <link name="linker_hand_l20_left_isaac_sim_thumb_link3">
    <inertial>
      <origin xyz="-0.0093737 -0.0118165 0.0040054" rpy="0. 0. 0."/>
      <mass value="0.0048328"/>
      <inertia ixx="0.0000006" ixy="0." ixz="-0." iyy="0.0000003" iyz="0.0000001" izz="0.0000003"/>
    </inertial>
    <visual>
      <origin xyz="-0. 0. 0." rpy="0. 0. -3.1415927"/>
      <geometry>
        <mesh filename="./meshes/linker_hand_l20_left_isaac_sim_thumb_link3_visuals_thumb_link3_node_STL_BINARY__mesh.obj" scale="1. 1. 1."/>
      </geometry>
    </visual>
    <visual>
      <origin xyz="-0. 0. 0." rpy="0. 0. -3.1415927"/>
      <geometry>
        <mesh filename="./meshes/linker_hand_l20_left_isaac_sim_thumb_link3_collisions_thumb_link3_node_STL_BINARY__mesh.obj" scale="1. 1. 1."/>
      </geometry>
    </visual>
    <collision>
      <origin xyz="-0. 0. 0." rpy="0. 0. -3.1415927"/>
      <geometry>
        <mesh filename="./meshes/linker_hand_l20_left_isaac_sim_thumb_link3_collisions_thumb_link3_node_STL_BINARY__mesh.obj" scale="1. 1. 1."/>
      </geometry>
    </collision>
  </link>
  <link name="linker_hand_l20_left_isaac_sim_thumb_link4">
    <inertial>
      <origin xyz="0.003056 -0.01054 0.0059367" rpy="0. 0. 0."/>
      <mass value="0.0065703"/>
      <inertia ixx="0.0000006" ixy="0." ixz="-0." iyy="0.0000002" iyz="0.0000001" izz="0.0000005"/>
    </inertial>
    <visual>
      <origin xyz="0. 0. 0." rpy="0. 0. -3.1415927"/>
      <geometry>
        <mesh filename="./meshes/linker_hand_l20_left_isaac_sim_thumb_link4_visuals_thumb_link4_node_STL_BINARY__mesh.obj" scale="1. 1. 1."/>
      </geometry>
    </visual>
    <visual>
      <origin xyz="0. 0. 0." rpy="0. 0. -3.1415927"/>
      <geometry>
        <mesh filename="./meshes/linker_hand_l20_left_isaac_sim_thumb_link4_collisions_thumb_link4_node_STL_BINARY__mesh.obj" scale="1. 1. 1."/>
      </geometry>
    </visual>
    <collision>
      <origin xyz="0. 0. 0." rpy="0. 0. -3.1415927"/>
      <geometry>
        <mesh filename="./meshes/linker_hand_l20_left_isaac_sim_thumb_link4_collisions_thumb_link4_node_STL_BINARY__mesh.obj" scale="1. 1. 1."/>
      </geometry>
    </collision>
  </link>
  <link name="linker_hand_l20_left_isaac_sim_thumb_link5">
    <inertial>
      <origin xyz="-0.001 -0. -0. " rpy="0. 0. 0."/>
      <mass value="0.0000016"/>
      <inertia ixx="0." ixy="-0." ixz="0." iyy="0." iyz="0." izz="0."/>
    </inertial>
    <visual>
      <origin xyz="0. -0. -0." rpy="0. -1.5707964 0. "/>
      <geometry>
        <mesh filename="./meshes/linker_hand_l20_left_isaac_sim_thumb_link5_visuals_thumb_link5_node_STL_BINARY__mesh.obj" scale="1. 1. 1."/>
      </geometry>
    </visual>
    <visual>
      <origin xyz="0. -0. -0." rpy="0. -1.5707964 0. "/>
      <geometry>
        <mesh filename="./meshes/linker_hand_l20_left_isaac_sim_thumb_link5_collisions_thumb_link5_node_STL_BINARY__mesh.obj" scale="1. 1. 1."/>
      </geometry>
    </visual>
    <collision>
      <origin xyz="0. -0. -0." rpy="0. -1.5707964 0. "/>
      <geometry>
        <mesh filename="./meshes/linker_hand_l20_left_isaac_sim_thumb_link5_collisions_thumb_link5_node_STL_BINARY__mesh.obj" scale="1. 1. 1."/>
      </geometry>
    </collision>
  </link>
  <link name="world">
    <inertial>
      <origin xyz="-0.021131 -0.0016302 0.056488 " rpy="0. 0. 0."/>
      <mass value="0.88556"/>
      <inertia ixx="0.0030595" ixy="0.0001226" ixz="-0.000627" iyy="0.0037783" iyz="0.0002702" izz="0.0020125"/>
    </inertial>
    <visual>
      <origin xyz="0. 0. 0." rpy="1.5707872 0. 0. "/>
      <geometry>
        <mesh filename="./meshes/world_visuals_link_base_mesh.obj" scale="1. 1. 1."/>
      </geometry>
    </visual>
    <visual>
      <origin xyz="0. 0. 0." rpy="0. 0. 0."/>
      <geometry>
        <mesh filename="./meshes/world_collisions_link_base_mesh.obj" scale="1. 1. 1."/>
      </geometry>
    </visual>
    <collision>
      <origin xyz="0. 0. 0." rpy="0. 0. 0."/>
      <geometry>
        <mesh filename="./meshes/world_collisions_link_base_mesh.obj" scale="1. 1. 1."/>
      </geometry>
    </collision>
  </link>
</robot>
